[*] Running ...
[*] Dataset loaded: C:\Development\cs5491-artificial-intelligence/problems/tsp_constructive\dataset\train50_dataset.npy with 64 instances.
Traceback (most recent call last):
  File "C:\Development\cs5491-artificial-intelligence/problems/tsp_constructive/eval.py", line 82, in <module>
    obj = eval_heuristic(node_positions[i])
          ^^^^^^^^^^^^^^^^^^^^^^^^^^^^^^^^^
  File "C:\Development\cs5491-artificial-intelligence/problems/tsp_constructive/eval.py", line 42, in eval_heuristic
    next_node = select_next_node(
                ^^^^^^^^^^^^^^^^^
  File "C:\Development\cs5491-artificial-intelligence\problems\tsp_constructive\gpt.py", line 10, in select_next_node_v2
    dest_distances = distance_matrix[destination_node]
                                                ^^^^^^^
  File "C:\Users\sunscreenDuckDuck\AppData\Local\Programs\Python\Python311\Lib\site-packages\numpy\core\_methods.py", line 49, in _sum
    return umr_sum(a, axis, dtype, out, keepdims, initial, where)
           ^^^^^^^^^^^^^^^^^^^^^^^^^^^^^^^^^^^^^^^^^^^^^^^^^^^^^^
numpy.exceptions.AxisError: axis 1 is out of bounds for array of dimension 1
